Workbook
Name Slicer_Diagnosis: #N/A

Sheet Dashboard

Sheet PIVOT TABLE
A1: KPI CARDS | D1: Metrics | E1: Actions | F1: Planned Target | G1: % of Target Achieved | J1: PIVOT TABLES AND HELPER COLUMNS | AI1: SLICERS | AO1: CHARTS
D2: Total Patients | E2: =GETPIVOTDATA("Patient ID",$A$5) -> 500 | F2: 650 | G2: =IFERROR(E2/F2,"0%") -> 0.76923077
A3: Total Patients | D3: Total Revenue | E3: =GETPIVOTDATA("Total Cost",$A$11) -> 6454833.7 | F3: 7000000 | G3: =IFERROR(E3/F3,"0%") -> 0.9221191 | AO3: Admission by Diagnosis
D4: Average Length of Stay | E4: =GETPIVOTDATA("Length of Stay",$A$17) -> 10.714 | F4: 5 | G4: =IFERROR(F4/E4,"0%") -> 0.46667911
A5: Count of Patient ID | D5: Average Satisfactory Score | E5: =GETPIVOTDATA("Satisfaction Score",$A$23) -> 5.312 | F5: 7 | G5: =IFERROR(E5/F5,"0%") -> 0.75885714 | J5: Admission by Diagnosis | P5: Revenue by Diagnosis | V5: Average Length of Stay by Diagnosis | AB5: Average Satisfaction by Diagnosis
A6: 500 | L6: Helper Column | R6: Helper Column | X6: Helper Column | AD6: Helper Column
J7: Row Labels | K7: Count of Patient ID | L7: Top Bar | M7: Other Bar | P7: Row Labels | Q7: Sum of Total Cost | R7: Top Bar | S7: Other Bar | V7: Row Labels | W7: Average of Length of Stay | X7: Top Bar | Y7: Other Bar | AB7: Row Labels | AC7: Average of Satisfaction Score | AD7: Top Bar | AE7: Other Bar
J8: Flu | K8: 38 | L8: =IF(K8=MAX($K$8:$K$17),K8,NA()) -> #N/A | M8: =IF(K8=MAX($K$8:$K$17),NA(),K8) -> 38 | P8: Asthma | Q8: 805567.6 | R8: =IF(Q8=MAX($Q$8:$Q$17),Q8,NA()) -> 805567.6 | S8: =IF(Q8=MAX($Q$8:$Q$17),NA(),Q8) -> #N/A | V8: Migraine | W8: 12.641026 | X8: =IF(W8=MAX($W$8:$W$17),W8,NA()) -> 12.641026 | Y8: =IF(W8=MAX($W$8:$W$17),NA(),W8) -> #N/A | AB8: Flu | AC8: 6.0526316 | AD8: =IF(AC8=MAX($AC$8:$AC$17),AC8,NA()) -> 6.0526316 | AE8: =IF(AC8=MAX($AC$8:$AC$17),NA(),AC8) -> #N/A
A9: Total Revenue | J9: Pneumonia | K9: 39 | L9: =IF(K9=MAX($K$8:$K$17),K9,NA()) -> #N/A | M9: =IF(K9=MAX($K$8:$K$17),NA(),K9) -> 39 | P9: Arthritis | Q9: 753375.85 | R9: =IF(Q9=MAX($Q$8:$Q$17),Q9,NA()) -> #N/A | S9: =IF(Q9=MAX($Q$8:$Q$17),NA(),Q9) -> 753375.85 | V9: Pneumonia | W9: 12.179487 | X9: =IF(W9=MAX($W$8:$W$17),W9,NA()) -> #N/A | Y9: =IF(W9=MAX($W$8:$W$17),NA(),W9) -> 12.179487 | AB9: Hypertension | AC9: 5.5740741 | AD9: =IF(AC9=MAX($AC$8:$AC$17),AC9,NA()) -> #N/A | AE9: =IF(AC9=MAX($AC$8:$AC$17),NA(),AC9) -> 5.5740741
J10: Migraine | K10: 39 | L10: =IF(K10=MAX($K$8:$K$17),K10,NA()) -> #N/A | M10: =IF(K10=MAX($K$8:$K$17),NA(),K10) -> 39 | P10: Diabetes | Q10: 723380.83 | R10: =IF(Q10=MAX($Q$8:$Q$17),Q10,NA()) -> #N/A | S10: =IF(Q10=MAX($Q$8:$Q$17),NA(),Q10) -> 723380.83 | V10: Covid-19 | W10: 11.957447 | X10: =IF(W10=MAX($W$8:$W$17),W10,NA()) -> #N/A | Y10: =IF(W10=MAX($W$8:$W$17),NA(),W10) -> 11.957447 | AB10: Arthritis | AC10: 5.5084746 | AD10: =IF(AC10=MAX($AC$8:$AC$17),AC10,NA()) -> #N/A | AE10: =IF(AC10=MAX($AC$8:$AC$17),NA(),AC10) -> 5.5084746
A11: Sum of Total Cost | J11: Covid-19 | K11: 47 | L11: =IF(K11=MAX($K$8:$K$17),K11,NA()) -> #N/A | M11: =IF(K11=MAX($K$8:$K$17),NA(),K11) -> 47 | P11: Hypertension | Q11: 688072.11 | R11: =IF(Q11=MAX($Q$8:$Q$17),Q11,NA()) -> #N/A | S11: =IF(Q11=MAX($Q$8:$Q$17),NA(),Q11) -> 688072.11 | V11: Cancer | W11: 10.711538 | X11: =IF(W11=MAX($W$8:$W$17),W11,NA()) -> #N/A | Y11: =IF(W11=MAX($W$8:$W$17),NA(),W11) -> 10.711538 | AB11: Asthma | AC11: 5.4923077 | AD11: =IF(AC11=MAX($AC$8:$AC$17),AC11,NA()) -> #N/A | AE11: =IF(AC11=MAX($AC$8:$AC$17),NA(),AC11) -> 5.4923077
A12: 6454833.7 | J12: Cancer | K12: 52 | L12: =IF(K12=MAX($K$8:$K$17),K12,NA()) -> #N/A | M12: =IF(K12=MAX($K$8:$K$17),NA(),K12) -> 52 | P12: Kidney Disease | Q12: 679795.18 | R12: =IF(Q12=MAX($Q$8:$Q$17),Q12,NA()) -> #N/A | S12: =IF(Q12=MAX($Q$8:$Q$17),NA(),Q12) -> 679795.18 | V12: Asthma | W12: 10.553846 | X12: =IF(W12=MAX($W$8:$W$17),W12,NA()) -> #N/A | Y12: =IF(W12=MAX($W$8:$W$17),NA(),W12) -> 10.553846 | AB12: Kidney Disease | AC12: 5.3518519 | AD12: =IF(AC12=MAX($AC$8:$AC$17),AC12,NA()) -> #N/A | AE12: =IF(AC12=MAX($AC$8:$AC$17),NA(),AC12) -> 5.3518519
J13: Diabetes | K13: 53 | L13: =IF(K13=MAX($K$8:$K$17),K13,NA()) -> #N/A | M13: =IF(K13=MAX($K$8:$K$17),NA(),K13) -> 53 | P13: Cancer | Q13: 647533.04 | R13: =IF(Q13=MAX($Q$8:$Q$17),Q13,NA()) -> #N/A | S13: =IF(Q13=MAX($Q$8:$Q$17),NA(),Q13) -> 647533.04 | V13: Flu | W13: 10.342105 | X13: =IF(W13=MAX($W$8:$W$17),W13,NA()) -> #N/A | Y13: =IF(W13=MAX($W$8:$W$17),NA(),W13) -> 10.342105 | AB13: Diabetes | AC13: 5.3207547 | AD13: =IF(AC13=MAX($AC$8:$AC$17),AC13,NA()) -> #N/A | AE13: =IF(AC13=MAX($AC$8:$AC$17),NA(),AC13) -> 5.3207547
J14: Kidney Disease | K14: 54 | L14: =IF(K14=MAX($K$8:$K$17),K14,NA()) -> #N/A | M14: =IF(K14=MAX($K$8:$K$17),NA(),K14) -> 54 | P14: Covid-19 | Q14: 624852.57 | R14: =IF(Q14=MAX($Q$8:$Q$17),Q14,NA()) -> #N/A | S14: =IF(Q14=MAX($Q$8:$Q$17),NA(),Q14) -> 624852.57 | V14: Hypertension | W14: 10.092593 | X14: =IF(W14=MAX($W$8:$W$17),W14,NA()) -> #N/A | Y14: =IF(W14=MAX($W$8:$W$17),NA(),W14) -> 10.092593 | AB14: Migraine | AC14: 5.1538462 | AD14: =IF(AC14=MAX($AC$8:$AC$17),AC14,NA()) -> #N/A | AE14: =IF(AC14=MAX($AC$8:$AC$17),NA(),AC14) -> 5.1538462
A15: Total Lenght of Stay | C15: Date | D15: =TODAY() -> 46220 | J15: Hypertension | K15: 54 | L15: =IF(K15=MAX($K$8:$K$17),K15,NA()) -> #N/A | M15: =IF(K15=MAX($K$8:$K$17),NA(),K15) -> 54 | P15: Pneumonia | Q15: 535640.37 | R15: =IF(Q15=MAX($Q$8:$Q$17),Q15,NA()) -> #N/A | S15: =IF(Q15=MAX($Q$8:$Q$17),NA(),Q15) -> 535640.37 | V15: Arthritis | W15: 10.084746 | X15: =IF(W15=MAX($W$8:$W$17),W15,NA()) -> #N/A | Y15: =IF(W15=MAX($W$8:$W$17),NA(),W15) -> 10.084746 | AB15: Cancer | AC15: 5.0192308 | AD15: =IF(AC15=MAX($AC$8:$AC$17),AC15,NA()) -> #N/A | AE15: =IF(AC15=MAX($AC$8:$AC$17),NA(),AC15) -> 5.0192308
J16: Arthritis | K16: 59 | L16: =IF(K16=MAX($K$8:$K$17),K16,NA()) -> #N/A | M16: =IF(K16=MAX($K$8:$K$17),NA(),K16) -> 59 | P16: Migraine | Q16: 500864.92 | R16: =IF(Q16=MAX($Q$8:$Q$17),Q16,NA()) -> #N/A | S16: =IF(Q16=MAX($Q$8:$Q$17),NA(),Q16) -> 500864.92 | V16: Diabetes | W16: 9.9056604 | X16: =IF(W16=MAX($W$8:$W$17),W16,NA()) -> #N/A | Y16: =IF(W16=MAX($W$8:$W$17),NA(),W16) -> 9.9056604 | AB16: Pneumonia | AC16: 4.7948718 | AD16: =IF(AC16=MAX($AC$8:$AC$17),AC16,NA()) -> #N/A | AE16: =IF(AC16=MAX($AC$8:$AC$17),NA(),AC16) -> 4.7948718
A17: Average of Length of Stay | J17: Asthma | K17: 65 | L17: =IF(K17=MAX($K$8:$K$17),K17,NA()) -> 65 | M17: =IF(K17=MAX($K$8:$K$17),NA(),K17) -> #N/A | P17: Flu | Q17: 495751.2 | R17: =IF(Q17=MAX($Q$8:$Q$17),Q17,NA()) -> #N/A | S17: =IF(Q17=MAX($Q$8:$Q$17),NA(),Q17) -> 495751.2 | V17: Kidney Disease | W17: 9.7407407 | X17: =IF(W17=MAX($W$8:$W$17),W17,NA()) -> #N/A | Y17: =IF(W17=MAX($W$8:$W$17),NA(),W17) -> 9.7407407 | AB17: Covid-19 | AC17: 4.7446809 | AD17: =IF(AC17=MAX($AC$8:$AC$17),AC17,NA()) -> #N/A | AE17: =IF(AC17=MAX($AC$8:$AC$17),NA(),AC17) -> 4.7446809
A18: 10.714
A21: Average Satisfactory Score
A23: Average Satisfaction Score | J23: Diagnosis and Helper Column Cell References | P23: Diagnosis Total Revenue and Helper Column Cell References | V23: Average Length of Stay and Helper Column Cell References | AB23: Average Length of Stay and Helper Column Cell References
A24: 5.312 | J24: Diagnosis | K24: Top Bar | L24: Other Bar | P24: Diagnosis | Q24: Top Bar | R24: Other Bar | V24: Diagnosis | W24: Top Bar | X24: Other Bar | AB24: Diagnosis | AC24: Top Bar | AD24: Other Bar | AO24: Revenue by Diagnosis
J25: =J8 -> Flu | K25: =L8 -> #N/A | L25: =M8 -> 38 | P25: =P8 -> Asthma | Q25: =R8 -> 805567.6 | R25: =S8 -> #N/A | V25: =V8 -> Migraine | W25: =X8 -> 12.641026 | X25: =Y8 -> #N/A | AB25: =AB8 -> Flu | AC25: =AD8 -> 6.0526316 | AD25: =AE8 -> #N/A
J26: =J9 -> Pneumonia | K26: =L9 -> #N/A | L26: =M9 -> 39 | P26: =P9 -> Arthritis | Q26: =R9 -> #N/A | R26: =S9 -> 753375.85 | V26: =V9 -> Pneumonia | W26: =X9 -> #N/A | X26: =Y9 -> 12.179487 | AB26: =AB9 -> Hypertension | AC26: =AD9 -> #N/A | AD26: =AE9 -> 5.5740741
J27: =J10 -> Migraine | K27: =L10 -> #N/A | L27: =M10 -> 39 | P27: =P10 -> Diabetes | Q27: =R10 -> #N/A | R27: =S10 -> 723380.83 | V27: =V10 -> Covid-19 | W27: =X10 -> #N/A | X27: =Y10 -> 11.957447 | AB27: =AB10 -> Arthritis | AC27: =AD10 -> #N/A | AD27: =AE10 -> 5.5084746
J28: =J11 -> Covid-19 | K28: =L11 -> #N/A | L28: =M11 -> 47 | P28: =P11 -> Hypertension | Q28: =R11 -> #N/A | R28: =S11 -> 688072.11 | V28: =V11 -> Cancer | W28: =X11 -> #N/A | X28: =Y11 -> 10.711538 | AB28: =AB11 -> Asthma | AC28: =AD11 -> #N/A | AD28: =AE11 -> 5.4923077
J29: =J12 -> Cancer | K29: =L12 -> #N/A | L29: =M12 -> 52 | P29: =P12 -> Kidney Disease | Q29: =R12 -> #N/A | R29: =S12 -> 679795.18 | V29: =V12 -> Asthma | W29: =X12 -> #N/A | X29: =Y12 -> 10.553846 | AB29: =AB12 -> Kidney Disease | AC29: =AD12 -> #N/A | AD29: =AE12 -> 5.3518519
J30: =J13 -> Diabetes | K30: =L13 -> #N/A | L30: =M13 -> 53 | P30: =P13 -> Cancer | Q30: =R13 -> #N/A | R30: =S13 -> 647533.04 | V30: =V13 -> Flu | W30: =X13 -> #N/A | X30: =Y13 -> 10.342105 | AB30: =AB13 -> Diabetes | AC30: =AD13 -> #N/A | AD30: =AE13 -> 5.3207547
J31: =J14 -> Kidney Disease | K31: =L14 -> #N/A | L31: =M14 -> 54 | P31: =P14 -> Covid-19 | Q31: =R14 -> #N/A | R31: =S14 -> 624852.57 | V31: =V14 -> Hypertension | W31: =X14 -> #N/A | X31: =Y14 -> 10.092593 | AB31: =AB14 -> Migraine | AC31: =AD14 -> #N/A | AD31: =AE14 -> 5.1538462
J32: =J15 -> Hypertension | K32: =L15 -> #N/A | L32: =M15 -> 54 | P32: =P15 -> Pneumonia | Q32: =R15 -> #N/A | R32: =S15 -> 535640.37 | V32: =V15 -> Arthritis | W32: =X15 -> #N/A | X32: =Y15 -> 10.084746 | AB32: =AB15 -> Cancer | AC32: =AD15 -> #N/A | AD32: =AE15 -> 5.0192308
J33: =J16 -> Arthritis | K33: =L16 -> #N/A | L33: =M16 -> 59 | P33: =P16 -> Migraine | Q33: =R16 -> #N/A | R33: =S16 -> 500864.92 | V33: =V16 -> Diabetes | W33: =X16 -> #N/A | X33: =Y16 -> 9.9056604 | AB33: =AB16 -> Pneumonia | AC33: =AD16 -> #N/A | AD33: =AE16 -> 4.7948718
J34: =J17 -> Asthma | K34: =L17 -> 65 | L34: =M17 -> #N/A | P34: =P17 -> Flu | Q34: =R17 -> #N/A | R34: =S17 -> 495751.2 | V34: =V17 -> Kidney Disease | W34: =X17 -> #N/A | X34: =Y17 -> 9.7407407 | AB34: =AB17 -> Covid-19 | AC34: =AD17 -> #N/A | AD34: =AE17 -> 4.7446809
AO45: Average Length of Stay by Diagnosis
AO67: Average Satisfaction by Diagnosis

Sheet KPI, CHARTS, SLICERS
A1: KPI CARDS | D1: TARTGETS | G1: CHARTS | I1: SLICER
A2: Total Patients | B2: Gotten from Patient ID | D2: 650 | G2: Admissions by Diagnosis | H2: Gotten from Patient ID and Diagnosis | I2: Diagnosis | J2: Gotten from Diagnosis
A3: Total Revenue | B3: Gotten from Total Cost | D3: 700000 | G3: Revenue by Diagnosis | H3: Gotten from Total Cost and Diagnosis
A4: Average Length of Stay | B4: Gotten from Length of Stay | D4: 5 | G4: Average Length of Stay by Diagnosis | H4: Gotten from Length of Stay and Diagnosis
A5: Average Satisfaction Score | B5: Gotten from Satisfaction Score | D5: 7 | G5: Average Satisfaction by Diagnosis | H5: Gotten from Satisfaction Score and Diagnosis

Sheet Cleaned Dataset
A1: Patient ID | B1: Admission Date | C1: Discharge Date | D1: Date of Birth | E1: Age | F1: Marital Status | G1: Occupation | H1: Diagnosis | I1: Severity Level | J1: Department | K1: Treatment Type | L1: Room Cost | M1: Lab Cost | N1: Medication Cost | O1: Treatment Cost | P1: Insurance Type | Q1: Doctor | R1: City | S1: Postcode | T1: Satisfaction Score | U1: Length of Stay | V1: Total Cost | W1: Cost Per Day | X1: Admission Month | Y1: Admission Year | Z1: Admission Month & Year | AA1: Day of the Week | AB1: Age Group | AC1: Patient Name | AD1: Gender | AE1: Length of Stay Category
A2: P10001 | B2: 45529 | C2: 45544 | D2: 37899 | E2: 22 | F2: Divorced | G2: Consultant | H2: Migraine | I2: Critical | J2: Neurology | K2: Emergency | L2: 2622.27 | M2: 625.1 | N2: 1295.76 | O2: 10228.96 | P2: Self-Pay | Q2: Dr. Wilson | R2: Sheffield | S2: SW59 5GM | T2: 3 | U2: =CAPSTONE_PROJECT[[#This Row],[Discharge Date]]-CAPSTONE_PROJECT[[#This Row],[Admission Date]] -> 15 | V2: =SUM(CAPSTONE_PROJECT[[#This Row],[Room Cost]:[Treatment Cost]]) -> 14772.09 | W2: =V2/U2 -> 984.806 | X2: =TEXT(CAPSTONE_PROJECT[[#This Row],[Admission Date]],"mmmm") -> August | Y2: =TEXT(CAPSTONE_PROJECT[[#This Row],[Admission Date]],"yyyy") -> 2024 | Z2: =TEXT(CAPSTONE_PROJECT[[#This Row],[Admission Date]],"mmm yyyy") -> Aug 2024 | AA2: =TEXT(CAPSTONE_PROJECT[[#This Row],[Admission Date]],"dddd") -> Sunday | AB2: =IF(CAPSTONE_PROJECT[[#This Row],[Age]]<=34,"Young Adults",IF(CAPSTONE_PROJECT[[#This Row],[Age]]<=59,"Adults","Elders")) -> Young Adults | AC2: =_xlfn.XLOOKUP(CAPSTONE_PROJECT[[#This Row],[Patient ID]],'Lookup table'!A:A,'Lookup table'!B:B,,0) -> Ethan Wilson | AD2: =_xlfn.XLOOKUP(CAPSTONE_PROJECT[[#This Row],[Patient ID]],'Lookup table'!A:A,'Lookup table'!C:C,,0) -> Male | AE2: =IF(CAPSTONE_PROJECT[[#This Row],[Length of Stay]]<=3,"Short Stay",IF(CAPSTONE_PROJECT[[#This Row],[Length of Stay]]<=7,"Moderate Stay",IF(CAPSTONE_PROJECT[[#This Row],[Length of Stay]]<=14,"Long Stay","Extended Stay"))) -> Extended Stay
A3: P10002 | B3: 45994 | C3: 45996 | D3: 16738 | E3: 80 | F3: Married | G3: Consultant | H3: Kidney Disease | I3: High | J3: Oncology | K3: Surgery | L3: 1558.08 | M3: 1656.97 | N3: 1052.71 | O3: 6599.48 | P3: Employer | Q3: Dr. Smith | R3: Manchester | S3: E40 8BS | T3: 6 | U3: =CAPSTONE_PROJECT[[#This Row],[Discharge Date]]-CAPSTONE_PROJECT[[#This Row],[Admission Date]] -> 2 | V3: =SUM(CAPSTONE_PROJECT[[#This Row],[Room Cost]:[Treatment Cost]]) -> 10867.24 | W3: =V3/U3 -> 5433.62 | X3: =TEXT(CAPSTONE_PROJECT[[#This Row],[Admission Date]],"mmmm") -> December | Y3: =TEXT(CAPSTONE_PROJECT[[#This Row],[Admission Date]],"yyyy") -> 2025 | Z3: =TEXT(CAPSTONE_PROJECT[[#This Row],[Admission Date]],"mmm yyyy") -> Dec 2025 | AA3: =TEXT(CAPSTONE_PROJECT[[#This Row],[Admission Date]],"dddd") -> Wednesday | AB3: =IF(CAPSTONE_PROJECT[[#This Row],[Age]]<=34,"Young Adults",IF(CAPSTONE_PROJECT[[#This Row],[Age]]<=59,"Adults","Elders")) -> Elders | AC3: =_xlfn.XLOOKUP(CAPSTONE_PROJECT[[#This Row],[Patient ID]],'Lookup table'!A:A,'Lookup table'!B:B,,0) -> Sarah Walker | AD3: =_xlfn.XLOOKUP(CAPSTONE_PROJECT[[#This Row],[Patient ID]],'Lookup table'!A:A,'Lookup table'!C:C,,0) -> Female | AE3: =IF(CAPSTONE_PROJECT[[#This Row],[Length of Stay]]<=3,"Short Stay",IF(CAPSTONE_PROJECT[[#This Row],[Length of Stay]]<=7,"Moderate Stay",IF(CAPSTONE_PROJECT[[#This Row],[Length of Stay]]<=14,"Long Stay","Extended Stay"))) -> Short Stay
A4: P10003 | B4: 45785 | C4: 45795 | D4: 35863 | E4: 28 | F4: Divorced | G4: Engineer | H4: Arthritis | I4: High | J4: Pediatrics | K4: Emergency | L4: 3153.83 | M4: 521.57 | N4: 701.42 | O4: 14612.55 | P4: NHS | Q4: Dr. Hall | R4: Sheffield | S4: E34 9DO | T4: 4 | U4: =CAPSTONE_PROJECT[[#This Row],[Discharge Date]]-CAPSTONE_PROJECT[[#This Row],[Admission Date]] -> 10 | V4: =SUM(CAPSTONE_PROJECT[[#This Row],[Room Cost]:[Treatment Cost]]) -> 18989.37 | W4: =V4/U4 -> 1898.937 | X4: =TEXT(CAPSTONE_PROJECT[[#This Row],[Admission Date]],"mmmm") -> May | Y4: =TEXT(CAPSTONE_PROJECT[[#This Row],[Admission Date]],"yyyy") -> 2025 | Z4: =TEXT(CAPSTONE_PROJECT[[#This Row],[Admission Date]],"mmm yyyy") -> May 2025 | AA4: =TEXT(CAPSTONE_PROJECT[[#This Row],[Admission Date]],"dddd") -> Thursday | AB4: =IF(CAPSTONE_PROJECT[[#This Row],[Age]]<=34,"Young Adults",IF(CAPSTONE_PROJECT[[#This Row],[Age]]<=59,"Adults","Elders")) -> Young Adults | AC4: =_xlfn.XLOOKUP(CAPSTONE_PROJECT[[#This Row],[Patient ID]],'Lookup table'!A:A,'Lookup table'!B:B,,0) -> James Jones | AD4: =_xlfn.XLOOKUP(CAPSTONE_PROJECT[[#This Row],[Patient ID]],'Lookup table'!A:A,'Lookup table'!C:C,,0) -> Male | AE4: =IF(CAPSTONE_PROJECT[[#This Row],[Length of Stay]]<=3,"Short Stay",IF(CAPSTONE_PROJECT[[#This Row],[Length of Stay]]<=7,"Moderate Stay",IF(CAPSTONE_PROJECT[[#This Row],[Length of Stay]]<=14,"Long Stay","Extended Stay"))) -> Long Stay
A5: P10004 | B5: 45767 | C5: 45777 | D5: 31464 | E5: 40 | F5: Widowed | G5: Manager | H5: Flu | I5: Low | J5: Respiratory | K5: Emergency | L5: 3156.73 | M5: 977.53 | N5: 1395.59 | O5: 5115.72 | P5: NHS | Q5: Dr. Hall | R5: Cardiff | S5: M76 3NU | T5: 2 | U5: =CAPSTONE_PROJECT[[#This Row],[Discharge Date]]-CAPSTONE_PROJECT[[#This Row],[Admission Date]] -> 10 | V5: =SUM(CAPSTONE_PROJECT[[#This Row],[Room Cost]:[Treatment Cost]]) -> 10645.57 | W5: =V5/U5 -> 1064.557 | X5: =TEXT(CAPSTONE_PROJECT[[#This Row],[Admission Date]],"mmmm") -> April | Y5: =TEXT(CAPSTONE_PROJECT[[#This Row],[Admission Date]],"yyyy") -> 2025 | Z5: =TEXT(CAPSTONE_PROJECT[[#This Row],[Admission Date]],"mmm yyyy") -> Apr 2025 | AA5: =TEXT(CAPSTONE_PROJECT[[#This Row],[Admission Date]],"dddd") -> Sunday | AB5: =IF(CAPSTONE_PROJECT[[#This Row],[Age]]<=34,"Young Adults",IF(CAPSTONE_PROJECT[[#This Row],[Age]]<=59,"Adults","Elders")) -> Adults | AC5: =_xlfn.XLOOKUP(CAPSTONE_PROJECT[[#This Row],[Patient ID]],'Lookup table'!A:A,'Lookup table'!B:B,,0) -> Sophia Wilson | AD5: =_xlfn.XLOOKUP(CAPSTONE_PROJECT[[#This Row],[Patient ID]],'Lookup table'!A:A,'Lookup table'!C:C,,0) -> Female | AE5: =IF(CAPSTONE_PROJECT[[#This Row],[Length of Stay]]<=3,"Short Stay",IF(CAPSTONE_PROJECT[[#This Row],[Length of Stay]]<=7,"Moderate Stay",IF(CAPSTONE_PROJECT[[#This Row],[Length of Stay]]<=14,"Long Stay","Extended Stay"))) -> Long Stay
A6: P10005 | B6: 45952 | C6: 45964 | D6: 32312 | E6: 37 | F6: Divorced | G6: Driver | H6: Diabetes | I6: Low | J6: Orthopedics | K6: Surgery | L6: 4982.28 | M6: 1827.2 | N6: 0 | O6: 0 | P6: NHS | Q6: Dr. Wilson | R6: Birmingham | S6: B27 2YR | T6: 4 | U6: =CAPSTONE_PROJECT[[#This Row],[Discharge Date]]-CAPSTONE_PROJECT[[#This Row],[Admission Date]] -> 12 | V6: =SUM(CAPSTONE_PROJECT[[#This Row],[Room Cost]:[Treatment Cost]]) -> 6809.48 | W6: =V6/U6 -> 567.45667 | X6: =TEXT(CAPSTONE_PROJECT[[#This Row],[Admission Date]],"mmmm") -> October | Y6: =TEXT(CAPSTONE_PROJECT[[#This Row],[Admission Date]],"yyyy") -> 2025 | Z6: =TEXT(CAPSTONE_PROJECT[[#This Row],[Admission Date]],"mmm yyyy") -> Oct 2025 | AA6: =TEXT(CAPSTONE_PROJECT[[#This Row],[Admission Date]],"dddd") -> Wednesday | AB6: =IF(CAPSTONE_PROJECT[[#This Row],[Age]]<=34,"Young Adults",IF(CAPSTONE_PROJECT[[#This Row],[Age]]<=59,"Adults","Elders")) -> Adults | AC6: =_xlfn.XLOOKUP(CAPSTONE_PROJECT[[#This Row],[Patient ID]],'Lookup table'!A:A,'Lookup table'!B:B,,0) -> Ethan Taylor | AD6: =_xlfn.XLOOKUP(CAPSTONE_PROJECT[[#This Row],[Patient ID]],'Lookup table'!A:A,'Lookup table'!C:C,,0) -> Male | AE6: =IF(CAPSTONE_PROJECT[[#This Row],[Length of Stay]]<=3,"Short Stay",IF(CAPSTONE_PROJECT[[#This Row],[Length of Stay]]<=7,"Moderate Stay",IF(CAPSTONE_PROJECT[[#This Row],[Length of Stay]]<=14,"Long Stay","Extended Stay"))) -> Long Stay
A7: P10006 | B7: 45968 | C7: 45969 | D7: 35128 | E7: 30 | F7: Single | G7: Cleaner | H7: Asthma | I7: Low | J7: Respiratory | K7: Outpatient | L7: 4401.16 | M7: 1385.2 | N7: 2493.38 | O7: 10620.37 | P7: Private | Q7: Dr. Green | R7: Manchester | S7: M58 6QS | T7: 3 | U7: =CAPSTONE_PROJECT[[#This Row],[Discharge Date]]-CAPSTONE_PROJECT[[#This Row],[Admission Date]] -> 1 | V7: =SUM(CAPSTONE_PROJECT[[#This Row],[Room Cost]:[Treatment Cost]]) -> 18900.11 | W7: =V7/U7 -> 18900.11 | X7: =TEXT(CAPSTONE_PROJECT[[#This Row],[Admission Date]],"mmmm") -> November | Y7: =TEXT(CAPSTONE_PROJECT[[#This Row],[Admission Date]],"yyyy") -> 2025 | Z7: =TEXT(CAPSTONE_PROJECT[[#This Row],[Admission Date]],"mmm yyyy") -> Nov 2025 | AA7: =TEXT(CAPSTONE_PROJECT[[#This Row],[Admission Date]],"dddd") -> Friday | AB7: =IF(CAPSTONE_PROJECT[[#This Row],[Age]]<=34,"Young Adults",IF(CAPSTONE_PROJECT[[#This Row],[Age]]<=59,"Adults","Elders")) -> Young Adults | AC7: =_xlfn.XLOOKUP(CAPSTONE_PROJECT[[#This Row],[Patient ID]],'Lookup table'!A:A,'Lookup table'!B:B,,0) -> Charlotte Hall | AD7: =_xlfn.XLOOKUP(CAPSTONE_PROJECT[[#This Row],[Patient ID]],'Lookup table'!A:A,'Lookup table'!C:C,,0) -> Female | AE7: =IF(CAPSTONE_PROJECT[[#This Row],[Length of Stay]]<=3,"Short Stay",IF(CAPSTONE_PROJECT[[#This Row],[Length of Stay]]<=7,"Moderate Stay",IF(CAPSTONE_PROJECT[[#This Row],[Length of Stay]]<=14,"Long Stay","Extended Stay"))) -> Short Stay
A8: P10007 | B8: 45994 | C8: 45998 | D8: 36355 | E8: 26 | F8: Divorced | G8: Student | H8: Covid-19 | I8: Critical | J8: Neurology | K8: Outpatient | L8: 2012.38 | M8: 1736.67 | N8: 1429.83 | O8: 7997.55 | P8: NHS | Q8: Dr. Smith | R8: Glasgow | S8: B38 8QT | T8: 2 | U8: =CAPSTONE_PROJECT[[#This Row],[Discharge Date]]-CAPSTONE_PROJECT[[#This Row],[Admission Date]] -> 4 | V8: =SUM(CAPSTONE_PROJECT[[#This Row],[Room Cost]:[Treatment Cost]]) -> 13176.43 | W8: =V8/U8 -> 3294.1075 | X8: =TEXT(CAPSTONE_PROJECT[[#This Row],[Admission Date]],"mmmm") -> December | Y8: =TEXT(CAPSTONE_PROJECT[[#This Row],[Admission Date]],"yyyy") -> 2025 | Z8: =TEXT(CAPSTONE_PROJECT[[#This Row],[Admission Date]],"mmm yyyy") -> Dec 2025 | AA8: =TEXT(CAPSTONE_PROJECT[[#This Row],[Admission Date]],"dddd") -> Wednesday | AB8: =IF(CAPSTONE_PROJECT[[#This Row],[Age]]<=34,"Young Adults",IF(CAPSTONE_PROJECT[[#This Row],[Age]]<=59,"Adults","Elders")) -> Young Adults | AC8: =_xlfn.XLOOKUP(CAPSTONE_PROJECT[[#This Row],[Patient ID]],'Lookup table'!A:A,'Lookup table'!B:B,,0) -> John Brown | AD8: =_xlfn.XLOOKUP(CAPSTONE_PROJECT[[#This Row],[Patient ID]],'Lookup table'!A:A,'Lookup table'!C:C,,0) -> Male | AE8: =IF(CAPSTONE_PROJECT[[#This Row],[Length of Stay]]<=3,"Short Stay",IF(CAPSTONE_PROJECT[[#This Row],[Length of Stay]]<=7,"Moderate Stay",IF(CAPSTONE_PROJECT[[#This Row],[Length of Stay]]<=14,"Long Stay","Extended Stay"))) -> Moderate Stay
A9: P10008 | B9: 45973 | C9: 45982 | D9: 23934 | E9: 60 | F9: Married | G9: Administrator | H9: Arthritis | I9: Low | J9: Emergency | K9: Emergency | L9: 617.84 | M9: 1264.62 | N9: 333.12 | O9: 15637.84 | P9: Self-Pay | Q9: Dr. White | R9: London | S9: B72 9KV | T9: 2 | U9: =CAPSTONE_PROJECT[[#This Row],[Discharge Date]]-CAPSTONE_PROJECT[[#This Row],[Admission Date]] -> 9 | V9: =SUM(CAPSTONE_PROJECT[[#This Row],[Room Cost]:[Treatment Cost]]) -> 17853.42 | W9: =V9/U9 -> 1983.7133 | X9: =TEXT(CAPSTONE_PROJECT[[#This Row],[Admission Date]],"mmmm") -> November | Y9: =TEXT(CAPSTONE_PROJECT[[#This Row],[Admission Date]],"yyyy") -> 2025 | Z9: =TEXT(CAPSTONE_PROJECT[[#This Row],[Admission Date]],"mmm yyyy") -> Nov 2025 | AA9: =TEXT(CAPSTONE_PROJECT[[#This Row],[Admission Date]],"dddd") -> Wednesday | AB9: =IF(CAPSTONE_PROJECT[[#This Row],[Age]]<=34,"Young Adults",IF(CAPSTONE_PROJECT[[#This Row],[Age]]<=59,"Adults","Elders")) -> Elders | AC9: =_xlfn.XLOOKUP(CAPSTONE_PROJECT[[#This Row],[Patient ID]],'Lookup table'!A:A,'Lookup table'!B:B,,0) -> Emma Martin | AD9: =_xlfn.XLOOKUP(CAPSTONE_PROJECT[[#This Row],[Patient ID]],'Lookup table'!A:A,'Lookup table'!C:C,,0) -> Female | AE9: =IF(CAPSTONE_PROJECT[[#This Row],[Length of Stay]]<=3,"Short Stay",IF(CAPSTONE_PROJECT[[#This Row],[Length of Stay]]<=7,"Moderate Stay",IF(CAPSTONE_PROJECT[[#This Row],[Length of Stay]]<=14,"Long Stay","Extended Stay"))) -> Long Stay
A10: P10009 | B10: 45521 | C10: 45525 | D10: 20044 | E10: 71 | F10: Single | G10: Chef | H10: Arthritis | I10: High | J10: General Medicine | K10: Inpatient | L10: 4804.73 | M10: 169.09 | N10: 2423.62 | O10: 4341.86 | P10: Employer | Q10: Dr. White | R10: Liverpool | S10: E24 5WY | T10: 7 | U10: =CAPSTONE_PROJECT[[#This Row],[Discharge Date]]-CAPSTONE_PROJECT[[#This Row],[Admission Date]] -> 4 | V10: =SUM(CAPSTONE_PROJECT[[#This Row],[Room Cost]:[Treatment Cost]]) -> 11739.3 | W10: =V10/U10 -> 2934.825 | X10: =TEXT(CAPSTONE_PROJECT[[#This Row],[Admission Date]],"mmmm") -> August | Y10: =TEXT(CAPSTONE_PROJECT[[#This Row],[Admission Date]],"yyyy") -> 2024 | Z10: =TEXT(CAPSTONE_PROJECT[[#This Row],[Admission Date]],"mmm yyyy") -> Aug 2024 | AA10: =TEXT(CAPSTONE_PROJECT[[#This Row],[Admission Date]],"dddd") -> Saturday | AB10: =IF(CAPSTONE_PROJECT[[#This Row],[Age]]<=34,"Young Adults",IF(CAPSTONE_PROJECT[[#This Row],[Age]]<=59,"Adults","Elders")) -> Elders | AC10: =_xlfn.XLOOKUP(CAPSTONE_PROJECT[[#This Row],[Patient ID]],'Lookup table'!A:A,'Lookup table'!B:B,,0) -> James Brown | AD10: =_xlfn.XLOOKUP(CAPSTONE_PROJECT[[#This Row],[Patient ID]],'Lookup table'!A:A,'Lookup table'!C:C,,0) -> Male | AE10: =IF(CAPSTONE_PROJECT[[#This Row],[Length of Stay]]<=3,"Short Stay",IF(CAPSTONE_PROJECT[[#This Row],[Length of Stay]]<=7,"Moderate Stay",IF(CAPSTONE_PROJECT[[#This Row],[Length of Stay]]<=14,"Long Stay","Extended Stay"))) -> Moderate Stay
A11: P10010 | B11: 45677 | C11: 45691 | D11: 33854 | E11: 33 | F11: Single | G11: Accountant | H11: Covid-19 | I11: Medium | J11: Neurology | K11: Emergency | L11: 5006.66 | M11: 1401.42 | N11: 2433.62 | O11: 2599.25 | P11: Employer | Q11: Dr. White | R11: Nottingham | S11: M63 8NI | T11: 1 | U11: =CAPSTONE_PROJECT[[#This Row],[Discharge Date]]-CAPSTONE_PROJECT[[#This Row],[Admission Date]] -> 14 | V11: =SUM(CAPSTONE_PROJECT[[#This Row],[Room Cost]:[Treatment Cost]]) -> 11440.95 | W11: =V11/U11 -> 817.21071 | X11: =TEXT(CAPSTONE_PROJECT[[#This Row],[Admission Date]],"mmmm") -> January | Y11: =TEXT(CAPSTONE_PROJECT[[#This Row],[Admission Date]],"yyyy") -> 2025 | Z11: =TEXT(CAPSTONE_PROJECT[[#This Row],[Admission Date]],"mmm yyyy") -> Jan 2025 | AA11: =TEXT(CAPSTONE_PROJECT[[#This Row],[Admission Date]],"dddd") -> Monday | AB11: =IF(CAPSTONE_PROJECT[[#This Row],[Age]]<=34,"Young Adults",IF(CAPSTONE_PROJECT[[#This Row],[Age]]<=59,"Adults","Elders")) -> Young Adults | AC11: =_xlfn.XLOOKUP(CAPSTONE_PROJECT[[#This Row],[Patient ID]],'Lookup table'!A:A,'Lookup table'!B:B,,0) -> Emily Martin | AD11: =_xlfn.XLOOKUP(CAPSTONE_PROJECT[[#This Row],[Patient ID]],'Lookup table'!A:A,'Lookup table'!C:C,,0) -> Female | AE11: =IF(CAPSTONE_PROJECT[[#This Row],[Length of Stay]]<=3,"Short Stay",IF(CAPSTONE_PROJECT[[#This Row],[Length of Stay]]<=7,"Moderate Stay",IF(CAPSTONE_PROJECT[[#This Row],[Length of Stay]]<=14,"Long Stay","Extended Stay"))) -> Long Stay
A12: P10011 | B12: 45501 | C12: 45511 | D12: 30317 | E12: 43 | F12: Married | G12: Administrator | H12: Cancer | I12: Critical | J12: Cardiology | K12: Inpatient | L12: 3673.34 | M12: 1505.01 | N12: 1405 | O12: 14937.06 | P12: Employer | Q12: Dr. Jones | R12: Cardiff | S12: SW10 7XB | T12: 8 | U12: =CAPSTONE_PROJECT[[#This Row],[Discharge Date]]-CAPSTONE_PROJECT[[#This Row],[Admission Date]] -> 10 | V12: =SUM(CAPSTONE_PROJECT[[#This Row],[Room Cost]:[Treatment Cost]]) -> 21520.41 | W12: =V12/U12 -> 2152.041 | X12: =TEXT(CAPSTONE_PROJECT[[#This Row],[Admission Date]],"mmmm") -> July | Y12: =TEXT(CAPSTONE_PROJECT[[#This Row],[Admission Date]],"yyyy") -> 2024 | Z12: =TEXT(CAPSTONE_PROJECT[[#This Row],[Admission Date]],"mmm yyyy") -> Jul 2024 | AA12: =TEXT(CAPSTONE_PROJECT[[#This Row],[Admission Date]],"dddd") -> Sunday | AB12: =IF(CAPSTONE_PROJECT[[#This Row],[Age]]<=34,"Young Adults",IF(CAPSTONE_PROJECT[[#This Row],[Age]]<=59,"Adults","Elders")) -> Adults | AC12: =_xlfn.XLOOKUP(CAPSTONE_PROJECT[[#This Row],[Patient ID]],'Lookup table'!A:A,'Lookup table'!B:B,,0) -> Lucas Hall | AD12: =_xlfn.XLOOKUP(CAPSTONE_PROJECT[[#This Row],[Patient ID]],'Lookup table'!A:A,'Lookup table'!C:C,,0) -> Male | AE12: =IF(CAPSTONE_PROJECT[[#This Row],[Length of Stay]]<=3,"Short Stay",IF(CAPSTONE_PROJECT[[#This Row],[Length of Stay]]<=7,"Moderate Stay",IF(CAPSTONE_PROJECT[[#This Row],[Length of Stay]]<=14,"Long Stay","Extended Stay"))) -> Long Stay
A13: P10012 | B13: 45467 | C13: 45487 | D13: 25579 | E13: 56 | F13: Divorced | G13: Cleaner | H13: Covid-19 | I13: Low | J13: Orthopedics | K13: Surgery | L13: 1332.63 | M13: 331.8 | N13: 1922.45 | O13: 13375.22 | P13: NHS | Q13: Dr. White | R13: Bristol | S13: N43 3CQ | T13: 4 | U13: =CAPSTONE_PROJECT[[#This Row],[Discharge Date]]-CAPSTONE_PROJECT[[#This Row],[Admission Date]] -> 20 | V13: =SUM(CAPSTONE_PROJECT[[#This Row],[Room Cost]:[Treatment Cost]]) -> 16962.1 | W13: =V13/U13 -> 848.105 | X13: =TEXT(CAPSTONE_PROJECT[[#This Row],[Admission Date]],"mmmm") -> June | Y13: =TEXT(CAPSTONE_PROJECT[[#This Row],[Admission Date]],"yyyy") -> 2024 | Z13: =TEXT(CAPSTONE_PROJECT[[#This Row],[Admission Date]],"mmm yyyy") -> Jun 2024 | AA13: =TEXT(CAPSTONE_PROJECT[[#This Row],[Admission Date]],"dddd") -> Monday | AB13: =IF(CAPSTONE_PROJECT[[#This Row],[Age]]<=34,"Young Adults",IF(CAPSTONE_PROJECT[[#This Row],[Age]]<=59,"Adults","Elders")) -> Adults | AC13: =_xlfn.XLOOKUP(CAPSTONE_PROJECT[[#This Row],[Patient ID]],'Lookup table'!A:A,'Lookup table'!B:B,,0) -> Olivia Wood | AD13: =_xlfn.XLOOKUP(CAPSTONE_PROJECT[[#This Row],[Patient ID]],'Lookup table'!A:A,'Lookup table'!C:C,,0) -> Female | AE13: =IF(CAPSTONE_PROJECT[[#This Row],[Length of Stay]]<=3,"Short Stay",IF(CAPSTONE_PROJECT[[#This Row],[Length of Stay]]<=7,"Moderate Stay",IF(CAPSTONE_PROJECT[[#This Row],[Length of Stay]]<=14,"Long Stay","Extended Stay"))) -> Extended Stay
... A501: P10500 | B501: 45616 | C501: 45618 | D501: 35261 | E501: 29 | F501: Divorced | G501: Nurse | H501: Diabetes | I501: Critical | J501: Cardiology | K501: Outpatient | L501: 2361.1 | M501: 543.24 | N501: 2991.43 | O501: 13393.01 | P501: Private | Q501: Dr. Hall | R501: Nottingham | S501: M79 9DW | T501: 2 | U501: =CAPSTONE_PROJECT[[#This Row],[Discharge Date]]-CAPSTONE_PROJECT[[#This Row],[Admission Date]] -> 2 | V501: =SUM(CAPSTONE_PROJECT[[#This Row],[Room Cost]:[Treatment Cost]]) -> 19288.78 | W501: =V501/U501 -> 9644.39 | X501: =TEXT(CAPSTONE_PROJECT[[#This Row],[Admission Date]],"mmmm") -> November | Y501: =TEXT(CAPSTONE_PROJECT[[#This Row],[Admission Date]],"yyyy") -> 2024 | Z501: =TEXT(CAPSTONE_PROJECT[[#This Row],[Admission Date]],"mmm yyyy") -> Nov 2024 | AA501: =TEXT(CAPSTONE_PROJECT[[#This Row],[Admission Date]],"dddd") -> Wednesday | AB501: =IF(CAPSTONE_PROJECT[[#This Row],[Age]]<=34,"Young Adults",IF(CAPSTONE_PROJECT[[#This Row],[Age]]<=59,"Adults","Elders")) -> Young Adults | AC501: =_xlfn.XLOOKUP(CAPSTONE_PROJECT[[#This Row],[Patient ID]],'Lookup table'!A:A,'Lookup table'!B:B,,0) -> Charlotte P Jones | AD501: =_xlfn.XLOOKUP(CAPSTONE_PROJECT[[#This Row],[Patient ID]],'Lookup table'!A:A,'Lookup table'!C:C,,0) -> Female | AE501: =IF(CAPSTONE_PROJECT[[#This Row],[Length of Stay]]<=3,"Short Stay",IF(CAPSTONE_PROJECT[[#This Row],[Length of Stay]]<=7,"Moderate Stay",IF(CAPSTONE_PROJECT[[#This Row],[Length of Stay]]<=14,"Long Stay","Extended Stay"))) -> Short Stay

Sheet Raw Data
A1: Patient ID | B1: Date of Birth | C1: Marital Status | D1: Occupation | E1: City | F1: Postcode | G1: Admission Date | I1: Discharge Date | J1: Diagnosis | K1: Severity Level | L1: Department | M1: Doctor | N1: Treatment Type | O1: Insurance Type | P1: Treatment Cost | Q1: Medication Cost | R1: Room Cost | S1: Lab Cost | T1: Satisfaction Score | U1: Age
A2: P10001 | B2: 37899 | C2: Divorced | D2: Consultant | E2: Sheffield | F2: SW59 5GM | G2: 45529 | I2: 45544 | J2: migraine | K2: Critical | L2: Neurology | M2: dr Wilson | N2: emergency | O2: Self-Pay | P2: 10228.96 | Q2: 1295.76 | R2: 2622.27 | S2: 625.1 | T2: 3 | U2: 22
A3: P10001 | B3: 37899 | C3: Divorced | D3: Consultant | E3: Sheffield | F3: SW59 5GM | G3: 45529 | I3: 45544 | J3: migraine | K3: Critical | L3: Neurology | M3: dr Wilson | N3: emergency | O3: Self-Pay | P3: 10228.96 | Q3: 1295.76 | R3: 2622.27 | S3: 625.1 | T3: 3 | U3: 22
A4: P10001 | B4: 37899 | C4: Divorced | D4: Consultant | E4: Sheffield | F4: SW59 5GM | G4: 45529 | I4: 45544 | J4: migraine | K4: Critical | L4: Neurology | M4: dr Wilson | N4: emergency | O4: Self-Pay | P4: 10228.96 | Q4: 1295.76 | R4: 2622.27 | S4: 625.1 | T4: 3 | U4: 22
A5: P10002 | B5: 16738 | C5: Married | D5: Consultant | E5: Manchester | F5: E40 8BS | G5: 45994 | I5: 45996 | J5: kidney Disease | K5: High | L5: oncolog | M5: Dr Smith | N5: Surgery | O5: Employer | P5: 6599.48 | Q5: 1052.71 | R5: 1558.08 | S5: 1656.97 | T5: 6 | U5: 80
A6: P10003 | B6: 35863 | C6: Divorced | D6: Engineer | E6: Sheffield | F6: E34 9DO | G6: 45785 | I6: 45795 | J6: Arthritis | K6: High | L6: Pediatrics | M6: Dr Hall | N6: Emergency | O6: NHS | P6: 14612.55 | Q6: 701.42 | R6: 3153.83 | S6: 521.57 | T6: 4 | U6: 28
A7: P10004 | B7: 31464 | C7: Widowed | D7: Manager | E7: Cardiff | F7: M76 3NU | G7: 45767 | I7: 45777 | J7: FLU | K7: Low | L7: Respiratory | M7: Dr Hall | N7: Emergency | O7: NHS | P7: 5115.72 | Q7: 1395.59 | R7: 3156.73 | S7: 977.53 | T7: 2 | U7: 40
A8: P10005 | B8: 32312 | C8: Divorced | D8: Driver | E8: Birmingham | F8: B27 2YR | G8: 45952 | I8: 45964 | J8: Diabetes | K8: Low | L8: Orthopedics | M8: Dr Wilson | N8: Surgery | O8: NHS | R8: 4982.28 | S8: 1827.2 | T8: 4 | U8: 37
A9: P10006 | B9: 35128 | C9: Single | D9: Cleaner | E9: Manchester | F9: M58 6QS | G9: 45968 | I9: 45969 | J9: asthma | K9: Low | L9: Respiratory | M9: Dr Green | N9: Outpatient | O9: Private | P9: 10620.37 | Q9: 2493.38 | R9: 4401.16 | S9: 1385.2 | T9: 3 | U9: 30
A10: P10007 | B10: 36355 | C10: Divorced | D10: Student | E10: Glasgow | F10: B38 8QT | G10: 45994 | I10: 45998 | J10: COVID-19 | K10: Critical | L10: Neurology | M10: Dr Smith | N10: Outpatient | O10: NHS | P10: 7997.55 | Q10: 1429.83 | R10: 2012.38 | S10: 1736.67 | T10: 2 | U10: 26
A11: P10008 | B11: 23934 | C11: Married | D11: Administrator | E11: London | F11: B72 9KV | G11: 45973 | I11: 45982 | J11: Arthritis | K11: Low | L11: Emergency | M11: Dr White | N11: Emergency | O11: Self-Pay | P11: 15637.84 | Q11: 333.12 | R11: 617.84 | S11: 1264.62 | T11: 2 | U11: 60
A12: P10009 | B12: 20044 | C12: Single | D12: Chef | E12: Liverpool | F12: E24 5WY | G12: 45521 | I12: 45525 | J12: Arthritis | K12: High | L12: General Medicine | M12: Dr White | N12: Inpatient | O12: Employer | P12: 4341.86 | Q12: 2423.62 | R12: 4804.73 | S12: 169.09 | T12: 7 | U12: 71
A13: P10010 | B13: 33854 | C13: Single | D13: Accountant | E13: Nottingham | F13: M63 8NI | G13: 45677 | I13: 45691 | J13: COVID-19 | K13: Medium | L13: Neurology | M13: Dr White | N13: Emergency | O13: Employer | P13: 2599.25 | Q13: 2433.62 | R13: 5006.66 | S13: 1401.42 | T13: 1 | U13: 33
A14: P10011 | B14: 30317 | C14: Married | D14: Administrator | E14: Cardiff | F14: SW10 7XB | G14: 45501 | I14: 45511 | J14: Cancer | K14: Critical | L14: Cardiology | M14: Dr Jones | N14: Inpatient | O14: Employer | P14: 14937.06 | Q14: 1405 | R14: 3673.34 | S14: 1505.01 | T14: 8 | U14: 43
A15: P10012 | B15: 25579 | C15: Divorced | D15: Cleaner | E15: Bristol | F15: N43 3CQ | G15: 45467 | I15: 45487 | J15: COVID-19 | K15: Low | L15: Orthopedics | M15: Dr White | N15: Surgery | O15: NHS | P15: 13375.22 | Q15: 1922.45 | R15: 1332.63 | S15: 331.8 | T15: 4 | U15: 56
A16: P10013 | B16: 34276 | C16: Divorced | D16: Nurse | E16: Nottingham | F16: E61 8UJ | G16: 45473 | I16: 45489 | J16: COVID-19 | K16: High | L16: Cardiology | M16: Dr White | N16: Inpatient | O16: Self-Pay | P16: 6046.74 | Q16: 2931.42 | R16: 413.69 | S16: 1737.35 | T16: 10 | U16: 32
A17: P10014 | B17: 27320 | C17: Single | D17: Administrator | E17: Birmingham | F17: E32 8OQ | G17: 45334 | I17: 45349 | J17: Kidney Disease | K17: Medium | L17: General Medicine | M17: Dr White | N17: Surgery | O17: Self-Pay | P17: 7255.77 | Q17: 2118.09 | R17: 2938.89 | S17: 166.46 | T17: 1 | U17: 51
A19: P10015 | B19: 24156 | C19: Widowed | D19: Nurse | E19: Glasgow | F19: E40 9MU | G19: 45986 | I19: 45999 | J19: Migraine | K19: High | L19: Oncology | M19: Dr Green | N19: Inpatient | O19: Private | P19: 11754.46 | Q19: 1423.15 | R19: 4301.18 | S19: 777.44 | T19: 3 | U19: 60
A20: P10016 | B20: 38571 | C20: Married | D20: Chef | E20: Sheffield | F20: N21 3WY | G20: 45523 | I20: 45528 | J20: asthma | K20: Medium | L20: Respiratory | M20: Dr Brown | N20: Emergency | P20: 7144.36 | Q20: 2206.09 | R20: 2141.96 | S20: 1284.25 | T20: 9 | U20: 20
A21: P10017 | B21: 28955 | C21: Married | D21: Chef | E21: Birmingham | F21: SW7 8LR | G21: 45772 | I21: 45779 | J21: Arthritis | K21: Low | L21: Neurology | M21: Dr Thomas | N21: Inpatient | O21: Self-Pay | P21: 13162.31 | Q21: 2017.94 | R21: 3870.53 | S21: 362.55 | T21: 7 | U21: 47
A22: P10018 | B22: 35654 | C22: Divorced | D22: Nurse | E22: Birmingham | F22: E37 8WE | G22: 45319 | I22: 45333 | J22: Diabetes | K22: Critical | L22: Respiratory | M22: Dr Hall | N22: Inpatient | O22: Self-Pay | P22: 1817 | Q22: 421.49 | R22: 1949.5 | S22: 1190.01 | T22: 1 | U22: 28
A23: P10019 | B23: 34462 | C23: Married | D23: Cleaner | E23: Birmingham | F23: SW55 1TL | G23: 45600 | I23: 45604 | J23: Diabetes | K23: Medium | L23: Emergency | M23: Dr Taylor | N23: Inpatient | O23: Self-Pay | P23: 10050.65 | Q23: 318.09 | R23: 749.34 | S23: 1159.37 | T23: 3 | U23: 32
A24: P10020 | B24: 36740 | C24: Single | D24: Manager | E24: Cardiff | F24: SW83 3YV | G24: 45942 | I24: 45955 | J24: ARTHRITIS | K24: Critical | L24: Respiratory | M24: Dr Taylor | N24: Outpatient | O24: NHS | P24: 2249.05 | Q24: 1486.11 | R24: 3852.7 | S24: 434.19 | T24: 2 | U24: 25
A25: P10021 | B25: 23879 | C25: Divorced | D25: Student | E25: Sheffield | F25: M50 6FP | G25: 45699 | I25: 45717 | J25: COVID-19 | K25: Critical | L25: General Medicine | M25: Dr Green | N25: Surgery | O25: Private | P25: 13708.61 | Q25: 1256.7 | R25: 3584.89 | S25: 1302.75 | T25: 1 | U25: 61
A26: P10022 | B26: 23776 | C26: Widowed | D26: Accountant | E26: London | F26: E86 7LQ | G26: 45627 | I26: 45637 | J26: Migraine | K26: Medium | L26: Cardiology | M26: Dr Taylor | N26: Emergency | P26: 1196.23 | Q26: 2919.39 | R26: 2110.85 | S26: 788.11 | T26: 8 | U26: 61
A27: P10023 | B27: 32367 | C27: Widowed | D27: Administrator | E27: Manchester | F27: SW34 8GT | G27: 45672 | I27: 45687 | J27: Hypertension | K27: High | L27: Respiratory | M27: Dr Wilson | N27: Inpatient | O27: Self-Pay | P27: 3575.83 | Q27: 1401.96 | R27: 3820.27 | S27: 1502.26 | T27: 5 | U27: 37
A29: P10024 | B29: 31951 | C29: Married | D29: Nurse | E29: Leeds | F29: M4 6RS | G29: 45358 | I29: 45376 | J29: Pneumonia | K29: High | L29: Respiratory | M29: Dr Green | N29: Outpatient | O29: Private | P29: 11410.25 | Q29: 3035.96 | R29: 668.93 | S29: 1523.94 | T29: 3 | U29: 38
A30: P10025 | B30: 35706 | C30: Widowed | D30: Administrator | E30: London | F30: E67 3JF | G30: 45420 | I30: 45431 | J30: Hypertension | K30: Medium | L30: General Medicine | M30: Dr Wilson | N30: Surgery | O30: Employer | P30: 9895.93 | Q30: 662.8 | R30: 771.06 | S30: 1367.82 | T30: 9 | U30: 28
A31: P10026 | B31: 31187 | C31: Single | D31: Engineer | E31: London | F31: B34 4YS | G31: 45838 | I31: 45841 | J31: Pneumonia | K31: Critical | L31: Cardiology | M31: Dr Jones | N31: Surgery | O31: Private | P31: 11973.65 | Q31: 816.87 | R31: 4080.49 | S31: 1707.25 | T31: 10 | U31: 41
A32: P10027 | B32: 18234 | C32: Married | D32: Manager | E32: Cardiff | F32: B14 6HO | G32: 45453 | I32: 45468 | J32: Flu | K32: Low | L32: Pediatrics | M32: Dr Jones | N32: Outpatient | O32: Private | P32: 2904.81 | Q32: 1416.15 | R32: 2571.54 | S32: 1819.77 | T32: 6 | U32: 76
A33: P10028 | B33: 35600 | C33: Married | D33: Chef | E33: Bristol | F33: E7 5PT | G33: 45612 | I33: 45619 | J33: Asthma | K33: Critical | L33: Pediatrics | M33: Dr Green | N33: Inpatient | O33: Self-Pay | P33: 14487.5 | Q33: 1362.74 | R33: 1285.25 | S33: 1527.29 | T33: 2 | U33: 28
A34: P10029 | B34: 17350 | C34: Single | D34: Nurse | E34: Manchester | F34: M48 6RL | G34: 45875 | I34: 45893 | J34: Cancer | K34: Medium | L34: Orthopedics | M34: Dr Hall | N34: Emergency | O34: Self-Pay | P34: 8733.25 | Q34: 2160.04 | R34: 431.7 | S34: 742.2 | T34: 9 | U34: 78
A35: P10030 | B35: 30564 | C35: Single | D35: Manager | E35: Bristol | F35: E54 5ZX | G35: 45627 | I35: 45647 | J35: Arthritis | K35: Low | L35: Respiratory | M35: Dr Thomas | N35: Outpatient | O35: Employer | P35: 12370.36 | Q35: 2514.64 | R35: 4052.05 | S35: 1344.06 | T35: 9 | U35: 42
A36: P10031 | B36: 35742 | C36: Single | D36: Cleaner | E36: Birmingham | F36: B27 9KV | G36: 45324 | I36: 45343 | J36: Hypertension | K36: Critical | L36: Emergency | M36: Dr White | N36: Outpatient | O36: Self-Pay | P36: 8943.12 | Q36: 711.3 | R36: 2958.63 | S36: 1442.6 | T36: 4 | U36: 28
A37: P10032 | B37: 20919 | C37: Divorced | D37: Accountant | E37: Manchester | F37: B87 9MM | G37: 45863 | I37: 45873 | J37: Cancer | K37: High | L37: Oncology | M37: Dr Thomas | N37: Inpatient | O37: Employer | P37: 6167.31 | Q37: 2957.73 | R37: 781.64 | S37: 957.8 | T37: 8 | U37: 69
A38: P10033 | B38: 21072 | C38: Divorced | D38: Cleaner | E38: Nottingham | F38: E88 3AR | G38: 45867 | I38: 45876 | J38: Asthma | K38: Medium | L38: Emergency | M38: Dr Jones | N38: Emergency | O38: Private | P38: 11357.46 | Q38: 1048.08 | R38: 2485.12 | S38: 1344.96 | T38: 9 | U38: 68
A39: P10034 | B39: 29213 | C39: Single | D39: Teacher | E39: Liverpool | F39: B78 2KJ | G39: 45330 | I39: 45336 | J39: Flu | K39: Critical | L39: Respiratory | M39: Dr Taylor | N39: Emergency | O39: NHS | P39: 5162.81 | Q39: 1754.8 | R39: 1055.07 | S39: 1539.95 | T39: 3 | U39: 46
... A49: P10044 | B49: 37669 | C49: Married | D49: Accountant | E49: Manchester | F49: E12 7MM | G49: 45444 | I49: 45452 | J49: Cancer | K49: Critical | L49: Cardiology | M49: Dr Brown | N49: Outpatient | O49: Employer | P49: 2353.86 | Q49: 1223.49 | R49: 3718.49 | S49: 726.29 | T49: 2 | U49: 23
A50: P10045 | B50: 21668 | C50: Married | D50: Chef | E50: Birmingham | F50: M10 5FS | G50: 46000 | I50: 46019 | J50: COVID-19 | K50: Low | L50: Emergency | M50: Dr Green | N50: Surgery | O50: Employer | R50: 1325.05 | S50: 1467.21 | T50: 1 | U50: 67
A51: P10046 | B51: 18817 | C51: Widowed | D51: Student | E51: Birmingham | F51: B85 7CY | G51: 45369 | I51: 45380 | J51: Kidney Disease | K51: High | L51: Orthopedics | M51: Dr Smith | N51: Inpatient | O51: Self-Pay | P51: 5044.22 | Q51: 1388.96 | R51: 1436.97 | S51: 686.04 | T51: 5 | U51: 74
...

Sheet Analysis

Sheet Lookup table
A1: Patient ID | B1: Patient Name | C1: Gender
A2: P10001 | B2: Ethan Wilson | C2: Male
A3: P10002 | B3: Sarah Walker | C3: Female
A4: P10003 | B4: James Jones | C4: Male
A5: P10004 | B5: Sophia Wilson | C5: Female
A6: P10005 | B6: Ethan Taylor | C6: Male
A7: P10006 | B7: Charlotte Hall | C7: Female
A8: P10007 | B8: John Brown | C8: Male
A9: P10008 | B9: Emma Martin | C9: Female
A10: P10009 | B10: James Brown | C10: Male
A11: P10010 | B11: Emily Martin | C11: Female
A12: P10011 | B12: Lucas Hall | C12: Male
... A501: P10500 | B501: Charlotte P Jones | C501: Female
